Workbook
Name _LEX1955: '[1]summary-targets'!#REF!
Name _LEX1955: '[1]summary-targets'!#REF!
Name _LEX1975: '[1]summary-targets'!#REF!
Name _LEX1975: '[1]summary-targets'!#REF!
Name _LEX2025: '[1]summary-targets'!#REF!
Name _LEX2025: '[1]summary-targets'!#REF!
Name _reg98: [2]whoreg!#REF!
Name _reg98: [2]whoreg!#REF!
Name _resul: '[3]slop-inter'!$A$45:$AG$48
Name _yellowF: #REF!
Name _yellowF: #REF!
Name _yellowM: #REF!
Name _yellowM: #REF!
Name data: #REF!
Name data: #REF!
Name Dist_Vars_byName: '[4]District Level Variables'!$B$1:$BD$201
Name eagd: #REF!
Name eagd: #REF!
Name Exchange_PPP: 'PPP Exchange Rates'!$1:$1048576
Name Exchange_Standard: 'Standard Exchange Rates'!$1:$1048576
Name fda: #REF!
Name fda: #REF!
Name fdae: [2]whoregeco!#REF!
Name fdae: [2]whoregeco!#REF!
Name fdageas: #REF!
Name fdageas: #REF!
Name fdas: #REF!
Name fdas: #REF!
Name GBDageD95: [5]Deaths!$A$1:$T$643
Name geasd: #REF!
Name geasd: #REF!
Name home: '[3]slop-inter'!$D$1:$F$1
Name inflation: '[6]Inflation Rates'!$C$1:$XFD$219
Name inflation: '[6]Inflation Rates'!$C$1:$XFD$219
Name inflation: 'Inflation Rates'!$C$1:$XFD$219
Name label: [3]lx!$D$1788:$E$1825
Name PA: #REF!
Name PA: #REF!
Name pop: #REF!
Name pop: #REF!
Name ppp: [7]Setup!#REF!
Name ppp: [7]Setup!#REF!
Name PrintAr2: #REF!
Name PrintAr2: #REF!
Name regeco98: [2]whoregeco!#REF!
Name regeco98: [2]whoregeco!#REF!
Name SlopeF: #REF!
Name SlopeF: #REF!
Name slopeintercept: '[8]intercept+slope projections'!$A$3:$H$29
Name slopeM: #REF!
Name slopeM: #REF!
Name sort1: '[8]intercept+slope projections'!$A$3:$B$29
Name sort2: '[8]intercept+slope projections'!$D$3:$F$29
Name sort3: '[8]intercept+slope projections'!$E$3:$F$29
Name sort4: '[8]intercept+slope projections'!$G$3:$H$29
Name SPSS: #REF!
Name SPSS: #REF!
Name year: '[8]intercept+slope projections'!$A$3:$A$29
Name yll: [7]Setup!#REF!
Name yll: [7]Setup!#REF!

Sheet Overview of Programs
A1: # | B1: Study Name | C1: Status | D1: Lead | E1: First QC | F1: Revision | G1: Second QC | H1: Iteration with PI | I1: Checked by Cornerstone | J1: Intervention | K1: PIs | L1: Impact (SD) | M1: Test Subjects (bold if significant) | N1: Impact source | O1: Country | P1: Region | Q1: PI CE Estimates | R1: Link to Eval Summary | S1: Link To Paper | T1: Notes | U1: Academic Citation
B4: color code: | C4: Not to be used
C5: Awaiting PI/RA response
C6: Initial calculations complete/In Progress
C7: Complete
C8: On hold

Sheet Comparisons
A2: I. Details of the Analysis
B4: Outcome Measure | C4: Additional Years of Education Induced, per $100 Spent
B5: Year of Analysis | C5: 2015
B6: Discount Rate | C6: 0.1
A9: II. Cost-Effectiveness Results and Sensitivity Analyses
B11: Cost-Effectiveness Graph
B12: Program | C12: Cost per Year of Student Attendance gained (Standard) | D12: Student Attendance Years per $100 (Standard) | E12: Student Attendance Years per $100 (PPP)
A13: 1
A14: 2
A15: 3
A16: 4
A17: 5
A18: 6
A19: 7
A20: 8
A21: 9
A22: 10
A25: III. Inflation and Exchange Rates Used in Calculations
A27: Year | B27: United States | C27: Country 1 | E27: Country 2 | G27: Country 3 | I27: Country 4 | K27: Country 5 | M27: Country 6 | O27: Country 7 | Q27: Country 8
B28: Inflation Rate | C28: Standard Exch. Rate | D28: PPP Exch. Rate | E28: Standard Exch. Rate | F28: PPP Exch. Rate | G28: Standard Exch. Rate | H28: PPP Exch. Rate | I28: Standard Exch. Rate | J28: PPP Exch. Rate | K28: Standard Exch. Rate | L28: PPP Exch. Rate | M28: Standard Exch. Rate | N28: PPP Exch. Rate | O28: Standard Exch. Rate | P28: PPP Exch. Rate | Q28: Standard Exch. Rate | R28: PPP Exch. Rate
A29: 1997
A30: 1998 | B30: 0.0113
A31: 1999 | B31: 0.0147
A32: 2000 | B32: 0.0216
A33: 2001 | B33: 0.0227
A34: 2002 | B34: 0.0162
A35: 2003 | B35: 0.0216
A36: 2004 | B36: 0.0283
A37: 2005 | B37: 0.0333
A38: 2006 | B38: 0.0325
A39: 2007 | B39: 0.0343
A40: 2008 | B40: 0.0219
A41: 2009 | B41: 0.0092
A42: 2010

Sheet 0 - Total Costs
A1: Study Title | B1: HIM
A2: Authors | B2: Banerjee, Chandrashekhar, Duflo, Dalpath, Floretta, Jackson, Kannan, Schrimpf, and Shrestha
A3: Publication Date
A4: Location | B4: Haryana, India
A5: Base Year | B5: 2016
A6: Year of Analysis | B6: 2018
A7: Outcome Measure | B7: Additional fully immunized children
A9: Demographics | B9: Number | C9: Unit | F9: Trainings | G9: Number | H9: Unit | L9: Gossips Identification | M9: Number | N9: Unit | P9: Implementation Costs: Meetings | Q9: Number | R9: Unit | T9: Government Costs | U9: Number | V9: Unit
A10: Intervention Duration | B10: 15 | C10: months | F10: Printing | G10: 125 | H10: 2017 INR | L10: Surveyors | M10: 426 | N10: man-days | P10: Lodging for meetings (launch + 6-month) | Q10: =50000+40000 -> 90000 | R10: 2017 INR | T10: ASHA incentives for mobilization | U10: 100 | V10: 2017 INR
A11: Months in 2017 | B11: 12 | C11: months | F11: Lunch and refreshments | G11: 7534 | H11: 2017 INR | L11: Monitors | M11: 133 | N11: man-days | P11: Transportation to monthly district meetings | Q11: 184011 | R11: 2017 INR | T11: ASHA incentives for FIC | U11: 150 | V11: 2017 INR
A12: Months in 2018 | B12: =B10-B11 -> 3 | C12: months | F12: J-PAL trainer lodging | G12: 15900 | H12: 2017 INR | L12: Field Manager | M12: 72 | N12: man-days | P12: Transportation to state-level meetings | Q12: 100200 | R12: 2017 INR | T12: AVD | U12: 75 | V12: 2017 INR
A13: Proportion of costs in 2017 | B13: =B11/B10 -> 0.8 | C13: percent | F13: J-PAL trainer per-diem | G13: 5899.98 | H13: 2017 INR | L13: Project Associate | M13: 57.8683 | N13: man-days | P13: Per-diem allowance (high level) | Q13: 800 | R13: 2017 INR | T13: Cost per BCG vaccine | U13: 3.25 | V13: 2017 INR
A14: Proportion of costs in 2018 | B14: =1-B13 -> 0.2 | C14: percent | F14: J-PAL transportation | G14: =5100+16900 -> 22000 | H14: 2017 INR | L14: Surveyor daily wage | M14: 350 | N14: 2017 INR | P14: Per-diem allowance (low level) | Q14: 300 | R14: 2017 INR | T14: Cost per Penta vaccines | U14: 137.15 | V14: 2017 INR
A15: Discount Rate | B15: =Comparisons!C6 -> 0.1 | C15: percent | F15: J-PAL staff lodging | G15: 1800 | H15: 2017 INR | L15: Monitors daily wage | M15: 525 | N15: 2017 INR | P15: Number of high level per-diem allowances | Q15: =70+1+1+2 -> 74 | R15: allowances | T15: Cost per measles vaccine | U15: 32.5 | V15: 2017 INR
A16: US-Local Exchange Rate, 2016 Standard | B16: 67.195 | C16: Rs/USD | F16: J-PAL staff transportation | G16: 14231.98 | H16: 2017 INR | L16: Field Manager daily wage | M16: 600 | N16: 2017 INR | P16: Number of low level per-diem allowances | Q16: 7 | R16: allowances | T16: Cost per 5 mL syringe | U16: 1.95 | V16: 2017 INR
A17: US-Local Exchange Rate, 2017 Standard | B17: 65.122 | C17: Rs/USD | F17: J-PAL staff per-diem | G17: =2263.63*22 -> 49799.86 | H17: 2017 INR | L17: Project Associate daily wage | M17: 896 | N17: 2017 INR | P17: Per-diem for launch + 6-month meetings | Q17: =1600*(2+5) -> 11200 | R17: 2017 INR | T17: Cost per 0.5 mL syringe | U17: 1.95 | V17: 2017 INR
A18: US-Local Exchange Rate, 2018, Standard | B18: 68.389 | C18: Rs/USD | F18: Number of trainers (Staff) | G18: 1 | H18: people | L18: Travel | M18: 94900 | N18: 2017 INR | T18: Cost per 0.1 mL syringe | U18: 2.6 | V18: 2017 INR
A19: Villages in entire sample | B19: 2360 | C19: villages | F19: Number of participants (Staff) | G19: 24 | H19: people | L19: Event space | M19: 1500 | N19: 2017 INR | T19: Number of BCG vaccines | U19: 24163 | V19: vaccines
A20: Total number of ANMs | B20: 1397 | C20: ANMs | F20: Master training materials | G20: =20526+42000+1400 -> 63926 | H20: 2017 INR | T20: Number of Penta vaccines | U20: =54873+52103+49026 -> 156002 | V20: vaccines
A21: Average US inflation, 2017 to 2018 | B21: 0.018 | C21: percent | F21: Master training food/bev | G21: 20934 | H21: 2017 INR | L21: Implementation Costs: Materials | M21: Number | N21: Unit | P21: Implementation Costs: Software | Q21: Number | R21: Unit | T21: Number of measles vaccines | U21: 49439 | V21: vaccines
A22: Average US inflation, 2016 to 2017 | B22: 0.022 | C22: percent | F22: Master training trainer lodging | G22: =7458.66666666666*6 -> 44752 | H22: 2017 INR | L22: Tablets + covers | M22: =7850+255+125 -> 8230 | N22: 2017 INR | P22: SANA software | Q22: 2026700 | R22: 2017 INR | T22: Number of 5 mL syringes | U22: 13535 | V22: syringes
A23: Average US inflation, 2016 to 2018 | B23: =AVERAGE(B21:B22) -> 0.02 | C23: percent | F23: Master training trainer transport | G23: =8400+12000 -> 20400 | H23: 2017 INR | L23: Bar codes (cost per roll) | M23: 175 | N23: 2017 INR | P23: Labor to develop software | Q23: 4200 | R23: 2017 INR | T23: Number of 0.5 mL syringes | U23: 225985 | V23: syringes
A24: Program Administration | B24: Number | C24: Unit | F24: Master training trainer per-diem | G24: 28800 | H24: 2017 INR | L24: Number of tablets | M24: 1200 | N24: tablets | P24: Server cost: SANA | Q24: 224428 | R24: 2017 INR | T24: Number of 0.1 mL syringes | U24: 26579 | V24: syringes
A25: Total field office rent and costs | B25: =628900+44932+61375+76400+13452+77750 -> 902809 | C25: 2017 INR | F25: Master training facilitator per-diem | G25: 14400 | H25: 2017 INR | L25: Number of bar codes | M25: 1676 | N25: rolls | P25: Server cost: SurveyCTO | Q25: 232960 | R25: 2017 INR | T25: ASHA incentives for mobilization | U25: =2622665/100 -> 26226.65 | V25: incentives
A26: Staff costs | B26: =17523362.8+2628504.42 -> 20151867 | C26: 2017 INR | F26: Trainee lodging | G26: 9150 | H26: 2017 INR | L26: ANM posters | M26: 16.576 | N26: 2017 INR | T26: ASHA incentives for FIC | U26: =6142800/150 -> 40952 | V26: incentives
A27: Intern daily salary | B27: 500 | C27: 2017 INR | F27: Trainee transport | G27: 61000 | H27: 2017 INR | L27: Number of posters | M27: 1600 | N27: posters | T27: AVD | U27: =1966999/75 -> 26226.653 | V27: incentives
A28: Number of intern days | B28: 210 | C28: man-days | F28: Trainee per-diem | G28: 12200 | H28: 2017 INR | L28: SIM cards | M28: 4267772 | N28: 2017 INR
F29: Number of trainers (Master) | G29: 2 | H29: trainings
F30: Number of participants (Master) | H30: people
A31: Targeting Costs | B31: Number | C31: Unit | F31: Number of master trainings | H31: trainings | L31: Implementation Costs: Phone Stuff | M31: Number | N31: Unit | P31: Pilot Costs | Q31: Number | R31: Unit
A32: IEC (Promotional Materials) | B32: 481040 | C32: 2017 INR | F32: ANM training materials | G32: 210000 | H32: 2017 INR | L32: Mobile recharges | M32: 16712390 | N32: 2017 INR | P32: Food and refreshments | Q32: =2660+2340+4390+1122 -> 10512 | R32: 2017 INR
A33: Travel to Gurgaon | B33: 1100 | C33: 2017 INR | F33: ANM training food/bev | G33: 420000 | H33: 2017 INR | L33: Congratulatory SMS | M33: 570271 | N33: SMS | P33: Per-diem allowance | Q33: =300*(4+7+11) -> 6600 | R33: 2017 INR
A34: Per-diem for monitors | B34: 900 | C34: 2017 INR | F34: ANM trainer per-diem | G34: 72000 | H34: 2017 INR | L34: Targeted reminder SMS | M34: 18685 | N34: SMS | P34: Travel to Gurgaon | Q34: =3*1100 -> 3300 | R34: 2017 INR
A35: Lunch and refreshments | B35: 612 | C35: 2017 INR | F35: ANM trainee per-diem | G35: 420000 | H35: 2017 INR | L35: ANM SMS | M35: =31405/M39 -> 65427.083 | N35: SMS
A36: Travel costs for core staff | B36: 600 | C36: 2017 INR | F36: ANM training travel + lodging | G36: =86400+3079.545454545*44+12087.2266666666*30+21000 -> 605516.8 | H36: 2017 INR | L36: Seeds SMS | M36: =14623/M40 -> 20309.722 | N36: SMS | P36: Monitoring Costs | Q36: Number | R36: Unit
F37: Per-diem allowance | G37: 210000 | H37: 2017 INR | L37: Voice calls | M37: =159676/M41 -> 456217.14 | N37: calls | P37: Travel (total costs) | Q37: 144000 | R37: 2017 INR
F38: Number of ANM trainings | G38: 45 | H38: trainings | L38: Exotel | M38: 37332 | N38: 2017 INR | P38: Cost per tablet | Q38: 3140 | R38: 2017 INR
F39: Number of trainers (ANM) | G39: 150 | H39: people | L39: Cost per SMS (regular) | M39: 0.48 | N39: 2017 INR | P39: Number of tablets | Q39: 50 | R39: tablets
F40: Number of participants (ANM) | G40: 1500 | H40: people | L40: Cost per SMS (seed) | M40: 0.72 | N40: 2017 INR
L41: Cost per voice call | M41: 0.35 | N41: 2017 INR
...

Sheet policy template -perunit
A1: Study Title | B1: HIM
A2: Authors | B2: Banerjee, Chandrashekhar, Duflo, Dalpath, Floretta, Jackson, Kannan, Schrimpf, and Shrestha
A3: Publication Date
A4: Location | B4: Haryana, India
A5: Base Year | B5: 2016
A6: Year of Analysis | B6: 2018 | L6: Networks Switch | M6: 0
A7: Outcome Measure | B7: Additional fully immunized children | L7: Gossip Switch | M7: 0
A9: Demographics | B9: Number | C9: Unit | F9: Trainings | G9: Number | H9: Unit | L9: Gossips Identification | M9: Number | N9: Unit | P9: Implementation Costs: Meetings | Q9: Number | R9: Unit | T9: Government Costs | U9: Number | V9: Unit
A10: Intervention Duration | B10: ='0 - Total Costs'!B10 -> 15 | C10: months | F10: Printing | G10: ='0 - Total Costs'!G10*$B$20 -> 0.052966102 | H10: 2017 INR | L10: Surveyors | M10: ='0 - Total Costs'!M10*B$20 -> 0.18050847 | N10: man-days | P10: Lodging for meetings (launch + 6-month) | Q10: ='0 - Total Costs'!Q10*$B$20 -> 38.135593 | R10: 2017 INR | T10: ASHA incentives for mobilization | U10: ='0 - Total Costs'!U10 -> 100 | V10: 2017 INR
A11: Villages in trusted only treatment | B11: 1 | C11: villages | F11: Lunch and refreshments | G11: ='0 - Total Costs'!G11*$B$20 -> 3.1923729 | H11: 2017 INR | L11: Monitors | M11: ='0 - Total Costs'!M11*B$20 -> 0.056355932 | N11: man-days | P11: Transportation to monthly district meetings | Q11: ='0 - Total Costs'!Q11*$B$20 -> 77.970763 | R11: 2017 INR | T11: ASHA incentives for FIC | U11: ='0 - Total Costs'!U11 -> 150 | V11: 2017 INR
F12: J-PAL trainer lodging | G12: ='0 - Total Costs'!G12*$B$20 -> 6.7372881 | H12: 2017 INR | L12: Field Manager | M12: ='0 - Total Costs'!M12*B$20 -> 0.030508475 | N12: man-days | P12: Transportation to staet-level meetings | Q12: ='0 - Total Costs'!Q12*$B$20 -> 42.457627 | R12: 2017 INR | T12: AVD | U12: ='0 - Total Costs'!U12 -> 75 | V12: 2017 INR
A13: Discount Rate | B13: =Comparisons!C6 -> 0.1 | C13: percent | F13: J-PAL trainer per-diem | G13: ='0 - Total Costs'!G13*$B$20 -> 2.4999915 | H13: 2017 INR | L13: Project Associate | M13: ='0 - Total Costs'!M13*B$20 -> 0.024520466 | N13: man-days | P13: Per-diem allowance (high level) | Q13: ='0 - Total Costs'!Q13 -> 800 | R13: 2017 INR | T13: Cost per BCG vaccine | U13: ='0 - Total Costs'!U13 -> 3.25 | V13: 2017 INR
A14: US-Local Exchange Rate, 2017 Standard | B14: 65.122 | C14: Rs/USD | F14: J-PAL trainer transportation | G14: ='0 - Total Costs'!G14*$B$20 -> 9.3220339 | H14: 2017 INR | L14: Surveyor daily wage | M14: ='0 - Total Costs'!M14*B20 -> 0.14830508 | N14: 2017 INR | P14: Per-diem allowance (low level) | Q14: ='0 - Total Costs'!Q14 -> 300 | R14: 2017 INR | T14: Cost per Penta vaccines | U14: ='0 - Total Costs'!U14 -> 137.15 | V14: 2017 INR
F15: J-PAL staff lodging | G15: ='0 - Total Costs'!G15*$B$20 -> 0.76271186 | H15: 2017 INR | L15: Monitors daily wage | M15: =B20*'0 - Total Costs'!M15 -> 0.22245763 | N15: 2017 INR | P15: Number of high level per-diem allowances | Q15: ='0 - Total Costs'!Q15*$B$20 -> 0.031355932 | R15: allowances | T15: Cost per measles vaccine | U15: ='0 - Total Costs'!U15 -> 32.5 | V15: 2017 INR
F16: J-PAL staff transportation | G16: ='0 - Total Costs'!G16*$B$20 -> 6.0305 | H16: 2017 INR | L16: Field Manager daily wage | M16: =B20*'0 - Total Costs'!M16 -> 0.25423729 | N16: 2017 INR | P16: Number of low level per-diem allowances | Q16: ='0 - Total Costs'!Q16*$B$20 -> 0.0029661017 | R16: allowances | T16: Cost per 5 mL syringe | U16: ='0 - Total Costs'!U16 -> 1.95 | V16: 2017 INR | Y16: Totals
A17: Villages in entire sample | B17: ='0 - Total Costs'!B19 -> 2360 | C17: villages | F17: J-PAL staff per-diem | G17: ='0 - Total Costs'!G17*$B$20 -> 21.101636 | H17: 2017 INR | L17: Project Associate daily wage | M17: ='0 - Total Costs'!M17*B20 -> 0.37966102 | N17: 2017 INR | P17: Per-diem for launch + 6-month meetings | Q17: ='0 - Total Costs'!Q17*$B$20 -> 4.7457627 | R17: 2017 INR | T17: Cost per 0.5 mL syringe | U17: ='0 - Total Costs'!U17 -> 1.95 | V17: 2017 INR | Y17: BCG | Z17: 0
A18: Villages in baseline sample | B18: 903 | C18: villages | F18: Number of trainers (Staff) | G18: ='0 - Total Costs'!G18 -> 1 | H18: people | L18: Travel | M18: ='0 - Total Costs'!M18*B$20 -> 40.211864 | N18: 2017 INR | T18: Cost per 0.1 mL syringe | U18: ='0 - Total Costs'!U18 -> 2.6 | V18: 2017 INR | Y18: Penta | Z18: 0
A19: Average children per village | B19: 91.024286 | C19: children | F19: Number of participants (Staff) | G19: ='0 - Total Costs'!G19 -> 24 | H19: people | L19: Event space | M19: ='0 - Total Costs'!M19*B$20 -> 0.63559322 | N19: 2017 INR | T19: Number of BCG vaccines | U19: =Z17*#REF! -> #REF! | V19: vaccines | Y19: Measles | Z19: 0
A20: Scaling factor for single village | B20: =B11/B17 -> 0.00042372881 | C20: percent | F20: Master training materials | G20: ='0 - Total Costs'!G20*$B$20 -> 27.087288 | H20: 2017 INR | T20: Number of Penta vaccines | U20: =Z18*#REF! -> #REF! | V20: vaccines
A21: Number of children in package treatment arm | B21: =B19*B11 -> 91.024286 | C21: children | F21: Master training food/bev | G21: ='0 - Total Costs'!G21*$B$20 -> 8.870339 | H21: 2017 INR | L21: Implementation Costs: Materials | M21: Number | N21: Unit | P21: Implementation Costs: Software | Q21: Number | R21: Unit | T21: Number of measles vaccines | U21: =Z19*#REF! -> #REF! | V21: vaccines | Y21: Penta-1 | Z21: 0
A22: Rate of full immunization at baseline | B22: 0.4 | C22: percent | F22: Master training trainer lodging | G22: ='0 - Total Costs'!G22*$B$20 -> 18.962712 | H22: 2017 INR | L22: Tablets + covers (rental costs) | M22: ='0 - Total Costs'!M22/M29 -> 228.61111 | N22: 2017 INR | P22: SANA software | Q22: ='0 - Total Costs'!Q22*$B$20 -> 858.77119 | R22: 2017 INR | T22: Number of 5 mL syringes | U22: =0 -> 0 | V22: syringes | Y22: Penta-2 | Z22: 0
A23: Number of fully immunized children at baseline | B23: =B22*B21 -> 36.409714 | C23: children | F23: Master training trainer transport | G23: ='0 - Total Costs'!G23*$B$20 -> 8.6440678 | H23: 2017 INR | L23: Bar codes (cost per roll) | M23: ='0 - Total Costs'!M23 -> 175 | N23: 2017 INR | P23: Labor to develop software | Q23: ='0 - Total Costs'!Q23*$B$20 -> 1.779661 | R23: 2017 INR | T23: Number of 0.5 mL syringes | U23: =SUM(U20:U21) -> #REF! | V23: syringes | Y23: Penta-3 | Z23: 0
A24: Number of ANMs in package treatment villages | B24: ='0 - Total Costs'!B20*B20 -> 0.59194915 | C24: ANMs | F24: Master training trainer per-diem | G24: ='0 - Total Costs'!G24*$B$20 -> 12.20339 | H24: 2017 INR | L24: Number of tablets | M24: ='0 - Total Costs'!M24*$B$20 -> 0.50847458 | N24: tablets | P24: Server cost: SANA | Q24: ='0 - Total Costs'!Q24*$B$20 -> 95.09661 | R24: 2017 INR | T24: Number of 0.1 mL syringes | U24: =U19 -> #REF! | V24: syringes
F25: Master training facilitator per-diem | G25: ='0 - Total Costs'!G25*$B$20 -> 6.1016949 | H25: 2017 INR | L25: Number of bar codes | M25: ='0 - Total Costs'!M25*$B$20 -> 0.71016949 | N25: rolls | P25: Server cost: SurveyCTO | Q25: ='0 - Total Costs'!Q25*$B$20 -> 98.711864 | R25: 2017 INR | T25: ASHA incentives for mobilization | U25: =SUM(U19:U21) -> #REF! | V25: incentives
A26: Number of gossips per village | B26: 6 | C26: people | F26: Trainee lodging | G26: ='0 - Total Costs'!G26*$B$20 -> 3.8771186 | H26: 2017 INR | L26: ANM posters | M26: ='0 - Total Costs'!M26 -> 16.576 | N26: 2017 INR | T26: ASHA incentives for FIC | U26: =U21 -> #REF! | V26: incentives
F27: Trainee transport | G27: ='0 - Total Costs'!G27*$B$20 -> 25.847458 | H27: 2017 INR | L27: Number of posters | M27: ='0 - Total Costs'!M27*B20 -> 0.6779661 | N27: posters | P27: Pilot Costs | Q27: Number | R27: Unit | T27: AVD | U27: =U25 -> #REF! | V27: incentives
A28: Program Administration | B28: Number | C28: Unit | F28: Trainee per-diem | G28: ='0 - Total Costs'!G28*$B$20 -> 5.1694915 | H28: 2017 INR | L28: SIM cards | M28: ='0 - Total Costs'!M28*B20 -> 1808.378 | N28: 2017 INR | P28: Food and refreshments | Q28: ='0 - Total Costs'!Q32*$B$20 -> 4.4542373 | R28: 2017 INR
A29: Field office rent and costs | B29: ='0 - Total Costs'!B25*B20 -> 382.54619 | C29: 2017 INR | F29: Number of trainers (Master) | G29: ='0 - Total Costs'!G29 -> 2 | H29: trainings | L29: Useful life of tablet | M29: 36 | N29: months | P29: Per-diem allowance | Q29: ='0 - Total Costs'!Q33*$B$20 -> 2.7966102 | R29: 2017 INR | T29: Mobile Recharges | U29: Number | V29: Unit
A30: Staff costs | B30: ='0 - Total Costs'!B26*B20 -> 8538.9268 | C30: 2017 INR | F30: Number of participants (Master) | G30: ='0 - Total Costs'!G30 -> 0 | H30: people | P30: Travel to Gurgaon | Q30: ='0 - Total Costs'!Q34*$B$20 -> 1.3983051 | R30: 2017 INR | T30: Number of low-slope incentives for BCG | U30: 0 | V30: vaccines
A31: Intern daily salary | B31: ='0 - Total Costs'!B27 -> 500 | C31: 2017 INR | F31: Number of master trainings | G31: ='0 - Total Costs'!G31 -> 0 | H31: trainings | L31: Implementation Costs: Phone Stuff | M31: Number | N31: Unit | T31: Number of low-slope incentives for Penta-1 | U31: 0 | V31: vaccines
A32: Number of intern days | B32: ='0 - Total Costs'!B28*B20 -> 0.088983051 | C32: man-days | F32: ANM training materials | G32: ='0 - Total Costs'!G32*$B$20 -> 88.983051 | H32: 2017 INR | L32: Mobile recharges | M32: =(SUM(U30:U32)*U40+U33*U41+U34*U42)+(SUM(U35:U37)*U43+U38*U44+U39*U45) -> 0 | N32: 2017 INR | P32: Monitoring Costs | Q32: Number | R32: Unit | T32: Number of low-slope incentives for Penta-2 | U32: 0 | V32: vaccines
F33: ANM training food/bev | G33: ='0 - Total Costs'!G33*$B$20 -> 177.9661 | H33: 2017 INR | L33: Congratulatory SMS | M33: =SUM(U19:U21) -> #REF! | N33: SMS | P33: Travel (total costs) | Q33: ='0 - Total Costs'!Q37*B20 -> 61.016949 | R33: 2017 INR | T33: Number of low-slope incentives for Penta-3 | U33: 0 | V33: vaccines
F34: ANM trainer per-diem | G34: ='0 - Total Costs'!G34*$B$20 -> 30.508475 | H34: 2017 INR | L34: Targeted reminder SMS | M34: =SUM(U19:U21)*M42*M44 -> #REF! | N34: SMS | P34: Cost per tablet | Q34: ='0 - Total Costs'!Q38 -> 3140 | R34: 2017 INR | T34: Number of low-slope incentives for measls | U34: 0 | V34: vaccines
A35: Targeting Costs | B35: Number | C35: Unit | F35: ANM trainee per-diem | G35: ='0 - Total Costs'!G35*$B$20 -> 177.9661 | H35: 2017 INR | L35: ANM SMS | M35: =B24*B10 -> 8.8792373 | N35: SMS | P35: Number of tablets | Q35: ='0 - Total Costs'!Q39*B20 -> 0.021186441 | R35: tablets | T35: Number of high-slope incentives for BCG | U35: 0 | V35: vaccines
A36: IEC (Promotional Materials) | B36: ='0 - Total Costs'!B32*$B$20 -> 203.83051 | C36: 2017 INR | F36: ANM training travel + lodging | G36: ='0 - Total Costs'!G36*$B$20 -> 256.57492 | H36: 2017 INR | L36: Seeds SMS (monthly) | M36: =B26*B11 -> 6 | N36: SMS | T36: Number of high-slope incentives for Penta-1 | U36: 0 | V36: vaccines
A37: Travel to Gurgaon | B37: ='0 - Total Costs'!B33*$B$20 -> 0.46610169 | C37: 2017 INR | F37: Per-diem allowance | G37: ='0 - Total Costs'!G37*$B$20 -> 88.983051 | H37: 2017 INR | L37: Voice calls (monthly) | M37: =M36 -> 6 | N37: calls | T37: Number of high-slope incentives for Penta-2 | U37: 0 | V37: vaccines
A38: Per-diem for monitors | B38: ='0 - Total Costs'!B34*$B$20 -> 0.38135593 | C38: 2017 INR | F38: Number of ANM trainings | G38: ='0 - Total Costs'!G38 -> 45 | H38: trainings | L38: Exotel | M38: ='0 - Total Costs'!M38*B$20 -> 15.818644 | N38: 2017 INR | T38: Number of high-slope incentives for Penta-3 | U38: 0 | V38: vaccines
A39: Lunch and refreshments | B39: ='0 - Total Costs'!B35*$B$20 -> 0.25932203 | C39: 2017 INR | F39: Number of trainers (ANM) | G39: ='0 - Total Costs'!G39 -> 150 | H39: people | L39: Cost per SMS (regular) | M39: ='0 - Total Costs'!M39 -> 0.48 | N39: 2017 INR | T39: Number of high-slope incentives for measls | U39: 0 | V39: vaccines
A40: Travel costs for core staff | B40: ='0 - Total Costs'!B36*$B$20 -> 0.25423729 | C40: 2017 INR | F40: Number of participants (ANM) | G40: ='0 - Total Costs'!G40 -> 1500 | H40: people | L40: Cost per SMS (seed) | M40: ='0 - Total Costs'!M40 -> 0.72 | N40: 2017 INR | T40: Low slope incentives, vaccines 1-3 | U40: 10 | V40: 2017 INR
L41: Cost per voice call | M41: ='0 - Total Costs'!M41 -> 0.35 | N41: 2017 INR | T41: Low slope incentives, vaccine 4 | U41: 60 | V41: 2017 INR
...

Sheet Inflation Rates
D1: Year | E1: =E2&"y" -> 1990y | F1: =F2&"y" -> 1991y | G1: =G2&"y" -> 1992y | H1: =H2&"y" -> 1993y | I1: =I2&"y" -> 1994y | J1: =J2&"y" -> 1995y | K1: =K2&"y" -> 1996y | L1: =L2&"y" -> 1997y | ... XFD1: =XFD2&"y" -> y
A2: Indicator Name | B2: Indicator Code | C2: Country Name | D2: Country Code | E2: 1990 | F2: 1991 | G2: 1992 | H2: 1993 | I2: 1994 | J2: 1995 | K2: 1996 | L2: 1997 | M2: 1998 | N2: 1999 | O2: 2000 | P2: 2001 | Q2: 2002 | R2: 2003 | S2: 2004 | T2: 2005 | U2: 2006 | V2: 2007 | W2: 2008 | X2: 2009 | Y2: 2010 | Z2: 2011 | AA2: 2012 | AB2: 2013
A3: Inflation, GDP deflator (annual %) | B3: NY.GDP.DEFL.KD.ZG | C3: United States | D3: USA | E3: 3.699951 | F3: 3.3261335 | G3: 2.2804256 | H3: 2.379793 | I3: 2.1287896 | J3: 2.0859922 | K3: 1.8263571 | L3: 1.7109594 | M3: 1.0847572 | N3: 1.4281215 | O3: 2.2722091 | P3: 2.2911273 | Q3: 1.5366495 | R3: 1.9983867 | S3: 2.7412332 | T3: 3.2073946 | U3: 3.0741277 | V3: 2.6538814 | W3: 1.9534819 | X3: 0.7696854 | Y3: 1.2104686 | Z3: 1.9639198 | AA3: 1.7482852 | AB3: 1.5141203
A6: Inflation, GDP deflator (annual %) | B6: NY.GDP.DEFL.KD.ZG | C6: Afghanistan | D6: AFG | E6: .. | F6: .. | G6: .. | H6: .. | I6: .. | J6: .. | K6: .. | L6: .. | M6: .. | N6: .. | O6: .. | P6: .. | Q6: .. | R6: 11.715672 | S6: 11.242729 | T6: 10.900268 | U6: 7.1712607 | V6: 22.382016 | W6: 2.1791033 | X6: -2.1070825 | Y6: 9.4377948 | Z6: 10.561139 | AA6: 8.3047609 | AB6: 3.7689159
A7: Inflation, GDP deflator (annual %) | B7: NY.GDP.DEFL.KD.ZG | C7: Albania | D7: ALB | E7: -0.46870766 | F7: 38.568343 | G7: 249.68344 | H7: 114.83565 | I7: 38.416495 | J7: 5.5733074 | K7: 28.418483 | L7: 13.943101 | M7: 13.556008 | N7: 4.4760685 | O7: 4.3215111 | P7: 3.458281 | Q7: 3.3001959 | R7: 3.3834861 | S7: 6.0077447 | T7: 3.4692522 | U7: 1.9952412 | V7: 1.9893036 | W7: 3.6937272 | X7: 2.4722096 | Y7: 4.7019901 | Z7: 1.8632165 | AA7: 1.3628712 | AB7: 0.78968101
A8: Inflation, GDP deflator (annual %) | B8: NY.GDP.DEFL.KD.ZG | C8: Algeria | D8: DZA | E8: 30.259598 | F8: 53.788604 | G8: 21.926115 | H8: 13.624425 | I8: 29.077647 | J8: 28.577038 | K8: 24.021904 | L8: 7.0019631 | M8: -3.1310887 | N8: 10.856408 | O8: 24.598099 | P8: -2.0071939 | Q8: 1.3204322 | R8: 8.3307285 | S8: 12.247624 | T8: 16.125362 | U8: 10.546696 | V8: 6.3953443 | W8: 15.762769 | X8: -11.161591 | Y8: 16.119787 | Z8: 17.785503 | AA8: 5.6273442 | AB8: 2.5270381
A9: Inflation, GDP deflator (annual %) | B9: NY.GDP.DEFL.KD.ZG | C9: American Samoa | D9: ASM | E9: .. | F9: .. | G9: .. | H9: .. | I9: .. | J9: .. | K9: .. | L9: .. | M9: .. | N9: .. | O9: .. | P9: .. | Q9: .. | R9: .. | S9: .. | T9: .. | U9: .. | V9: .. | W9: .. | X9: .. | Y9: .. | Z9: .. | AA9: .. | AB9: ..
A10: Inflation, GDP deflator (annual %) | B10: NY.GDP.DEFL.KD.ZG | C10: Andorra | D10: ADO | E10: 7.3262512 | F10: 6.9351393 | G10: 6.7107714 | H10: 4.5372411 | I10: 3.8798421 | J10: 4.9331298 | K10: 0.79718278 | L10: 2.2281515 | M10: 1.4995616 | N10: 2.7319769 | O10: 4.5139798 | P10: 2.77 | Q10: 3.3999999 | R10: 2.88 | S10: 3.35 | T10: 3.1 | U10: 3.2 | V10: 3.87 | W10: 3.1850987 | X10: .. | Y10: .. | Z10: .. | AA10: .. | AB10: ..
A11: Inflation, GDP deflator (annual %) | B11: NY.GDP.DEFL.KD.ZG | C11: Angola | D11: AGO | E11: 10.858624 | F11: 165.39958 | G11: 252.7405 | H11: 1253.2806 | I11: 2124.6072 | J11: 1895.2065 | K11: 5399.5262 | L11: 94.319571 | M11: 35.316825 | N11: 556.93926 | O11: 418.23295 | P11: 106.32249 | Q11: 142.47819 | R11: 84.886475 | S11: 39.792942 | T11: 26.816294 | U11: 13.04118 | V11: 12.616432 | W11: 19.681609 | X11: -7.4188384 | Y11: 22.393924 | Z11: 24.167172 | AA11: 7.0276475 | AB11: 2.5111103
A12: Inflation, GDP deflator (annual %) | B12: NY.GDP.DEFL.KD.ZG | C12: Antigua and Barbuda | D12: ATG | E12: 2.2624687 | F12: 2.7142022 | G12: 2.3904149 | H12: 2.2240747 | I12: 3.020839 | J12: 3.1268992 | K12: 2.5750158 | L12: 2.1747109 | M12: 2.4160861 | N12: 0.96955078 | O12: 14.975686 | P12: 1.9910954 | Q12: 0.70700551 | R12: -1.2067408 | S12: 1.5892508 | T12: 4.3219409 | U12: 0.33413296 | V12: 3.7246722 | W12: 4.4479527 | X12: 1.7712865 | Y12: 1.4138879 | Z12: 1.2813743 | AA12: 2.5513272 | AB12: 2.3450641
A13: Inflation, GDP deflator (annual %) | B13: NY.GDP.DEFL.KD.ZG | C13: Argentina | D13: ARG | E13: 2076.7935 | F13: 132.95323 | G13: 11.92076 | H13: -1.4666599 | I13: 24.587524 | J13: 3.1651236 | K13: -0.052376507 | L13: -0.46391279 | M13: -1.7052792 | N13: -1.8365582 | O13: 1.0372869 | P13: -1.0957672 | Q13: 30.555203 | R13: 10.495702 | S13: 7.9257364 | T13: 10.620156 | U13: 15.28385 | V13: 17.63826 | W13: 21.213723 | X13: 9.8845046 | Y13: 17.513685 | Z13: 17.204583 | AA13: 18.055141 | AB13: 18.543698
A14: Inflation, GDP deflator (annual %) | B14: NY.GDP.DEFL.KD.ZG | C14: Armenia | D14: ARM | E14: .. | F14: 79.386104 | G14: 568.80733 | H14: 1391.1665 | I14: 4107.2968 | J14: 161.16392 | K14: 19.59177 | L14: 17.735995 | M14: 10.698498 | N14: 0.053804078 | O14: -1.373676 | P14: 4.0691399 | Q14: 2.3697878 | R14: 4.5610984 | S14: 6.3095327 | T14: 3.2398363 | U14: 4.6198577 | V14: 4.2327704 | W14: 5.9895624 | X14: 2.5569351 | Y14: 7.7687155 | Z14: 4.28155 | AA14: -1.2157086 | AB14: 3.1913884
A15: Inflation, GDP deflator (annual %) | B15: NY.GDP.DEFL.KD.ZG | C15: Aruba | D15: ABW | E15: .. | F15: .. | G15: .. | H15: .. | I15: .. | J15: -1.9349795 | K15: -3.0891098 | L15: 4.0739304 | M15: 7.4754938 | N15: -1.0192115 | O15: 9.1427411 | P15: 4.7662208 | Q15: 0.61671322 | R15: -3.1505348 | S15: 8.9577248 | T15: 4.2136963 | U15: 1.4908946 | V15: 12.462489 | W15: 14.275706 | X15: -5.1320556 | Y15: .. | Z15: .. | AA15: .. | AB15: ..
A16: Inflation, GDP deflator (annual %) | B16: NY.GDP.DEFL.KD.ZG | C16: Australia | D16: AUS | E16: 5.1478376 | F16: 2.6393887 | G16: 1.6730756 | H16: 0.76884958 | I16: 1.0250911 | J16: 2.4482731 | K16: 2.6763353 | L16: 1.2251342 | M16: 1.2784561 | N16: 0.33458501 | O16: 2.5635191 | P16: 4.7047498 | Q16: 2.8655882 | R16: 3.1134022 | S16: 3.2835446 | T16: 3.7079639 | U16: 5.0586325 | V16: 4.9825597 | W16: 4.5384532 | X16: 4.9317299 | Y16: 1.0102778 | Z16: 6.1356205 | AA16: 1.9588802 | AB16: -0.29103246
A17: Inflation, GDP deflator (annual %) | B17: NY.GDP.DEFL.KD.ZG | C17: Austria | D17: AUT | E17: 2.9996804 | F17: 3.6418715 | G17: 3.4790931 | H17: 2.7570846 | I17: 2.5249429 | J17: 1.813918 | K17: 0.81197607 | L17: -0.22090193 | M17: 0.32032606 | N17: 0.28342109 | O17: 0.91921702 | P17: 1.8738007 | Q17: 1.239627 | R17: 1.1496102 | S17: 1.683295 | T17: 2.0391816 | U17: 1.8844718 | V17: 2.0048146 | W17: 1.7228742 | X17: 1.5775652 | Y17: 1.4407855 | Z17: 2.0435017 | AA17: 1.7089737 | AB17: 1.6170558
A18: Inflation, GDP deflator (annual %) | B18: NY.GDP.DEFL.KD.ZG | C18: Azerbaijan | D18: AZE | E18: .. | F18: 83.549512 | G18: 1065.3292 | H18: 747.56698 | I18: 1385.202 | J18: 545.6953 | K18: 26.421013 | L18: 9.2402137 | M18: -0.96393089 | N18: 2.1610078 | O18: 12.493369 | P18: 2.5150101 | Q18: 3.1193184 | R18: 6.0086142 | S18: 8.3151767 | T18: 16.139422 | U18: 11.301397 | V18: 20.98171 | W18: 27.761953 | X18: -18.929731 | Y18: 13.756553 | Z18: 22.566087 | AA18: 1.4413445 | AB18: 1.0210666
A19: Inflation, GDP deflator (annual %) | B19: NY.GDP.DEFL.KD.ZG | C19: Bahamas, The | D19: BHS | E19: 5.0737112 | F19: 2.5565382 | G19: 3.9055659 | H19: -0.85198361 | I19: 2.1833662 | J19: 0.80243636 | K19: 0.98424379 | L19: 34.687616 | M19: 3.0493128 | N19: 4.9509405 | O19: 0.92183066 | P19: 0.35359062 | Q19: 3.9608188 | R19: 1.1546133 | S19: 1.1944872 | T19: 5.0568275 | U19: 0.82796732 | V19: 2.9475256 | W19: 1.4888899 | X19: -1.0365421 | Y19: -0.12152524 | Z19: -1.8256277 | AA19: 1.648792 | AB19: ..
A20: Inflation, GDP deflator (annual %) | B20: NY.GDP.DEFL.KD.ZG | C20: Bahrain | D20: BHR | E20: 4.8266931 | F20: -1.8825275 | G20: -3.5326488 | H20: -3.025817 | I20: 7.3311889 | J20: 1.0906712 | K20: 0.19672117 | L20: 0.93171529 | M20: -7.0574088 | N20: 2.6564307 | O20: 29.991486 | P20: -3.3638767 | Q20: 3.5646423 | R20: 8.4449435 | S20: 10.991078 | T20: 13.734991 | U20: 8.8423562 | V20: 8.4356733 | W20: 11.373776 | X20: -12.998703 | Y20: 7.4385878 | Z20: 10.63034 | AA20: 1.1006975 | AB20: 2.3694171
A21: Inflation, GDP deflator (annual %) | B21: NY.GDP.DEFL.KD.ZG | C21: Bangladesh | D21: BGD | E21: 6.3355972 | F21: 6.5962352 | G21: 2.9763698 | H21: 0.28696994 | I21: 3.7718272 | J21: 7.3453322 | K21: 4.2345036 | L21: 3.0900972 | M21: 5.2743663 | N21: 4.6557307 | O21: 1.8596609 | P21: 1.5853946 | Q21: 3.1953751 | R21: 4.5276296 | S21: 4.2404288 | T21: 5.0747149 | U21: 5.1723735 | V21: 6.7864503 | W21: 8.7891012 | X21: 6.5209543 | Y21: 6.4736227 | Z21: 7.5319114 | AA21: 8.4801147 | AB21: 6.6233843
A22: Inflation, GDP deflator (annual %) | B22: NY.GDP.DEFL.KD.ZG | C22: Barbados | D22: BRB | E22: 24.740742 | F22: 2.1742885 | G22: 1.7176882 | H22: 4.4446092 | I22: 1.1174457 | J22: 3.6007715 | K22: 4.7067636 | L22: -0.65504454 | M22: 8.301261 | N22: 2.1379519 | O22: 0.67065958 | P22: 2.3817192 | Q22: 1.1271126 | R22: 1.2404815 | S22: 5.7748824 | T22: 6.6171789 | U22: 4.8736436 | V22: 2.8980939 | W22: 0.28292564 | X22: 5.492194 | Y22: -3.705047 | Z22: -2.2033191 | AA22: -3.306155 | AB22: ..
A23: Inflation, GDP deflator (annual %) | B23: NY.GDP.DEFL.KD.ZG | C23: Belarus | D23: BLR | E23: .. | F23: 103.59791 | G23: 1074.1412 | H23: 1053.449 | I23: 1945.1071 | J23: 661.493 | K23: 53.715001 | L23: 71.649451 | M23: 76.580409 | N23: 316.79333 | O23: 185.2908 | P23: 79.534573 | Q23: 44.893739 | R23: 30.685321 | S23: 22.675123 | T23: 18.927696 | U23: 10.750637 | V23: 12.823553 | W23: 21.160491 | X23: 5.7222859 | Y23: 11.071486 | Z23: 71.179529 | AA23: 75.438581 | AB23: 19.002897
A24: Inflation, GDP deflator (annual %) | B24: NY.GDP.DEFL.KD.ZG | C24: Belgium | D24: BEL | E24: 2.8124032 | F24: 2.8766246 | G24: 3.4245245 | H24: 3.9932318 | I24: 2.0943051 | J24: 1.2207694 | K24: 0.37235765 | L24: 0.87104965 | M24: 1.8702952 | N24: 0.31387861 | O24: 1.9787055 | P24: 2.0505637 | Q24: 2.0067862 | R24: 1.9829917 | S24: 2.1345637 | T24: 2.3777128 | U24: 2.3441939 | V24: 2.375905 | W24: 2.1383592 | X24: 1.1864466 | Y24: 2.0530829 | Z24: 1.9958346 | AA24: 1.9323239 | AB24: 1.6200574
A25: Inflation, GDP deflator (annual %) | B25: NY.GDP.DEFL.KD.ZG | C25: Belize | D25: BLZ | E25: 2.8132817 | F25: -2.5607132 | G25: 3.9934962 | H25: 1.6515198 | I25: 3.588105 | J25: 6.0789813 | K25: 1.9687101 | L25: -1.4770146 | M25: 1.5030976 | N25: -2.235249 | O25: 0.43700258 | P25: -0.18627188 | Q25: 1.7687458 | R25: -2.8771609 | S25: 2.0714008 | T25: 2.287547 | U25: 4.3642885 | V25: 4.7484166 | W25: 2.1565753 | X25: -2.5499769 | Y25: 0.60822354 | Z25: 5.0736256 | AA25: 1.5288662 | AB25: 1.3374336
A26: Inflation, GDP deflator (annual %) | B26: NY.GDP.DEFL.KD.ZG | C26: Benin | D26: BEN | E26: 2.1765969 | F26: 0.75662014 | G26: 3.0251345 | H26: 2.3783218 | I26: 35.030113 | J26: 15.099452 | K26: 6.9072937 | L26: 3.6675092 | M26: 5.2316047 | N26: 0.43636213 | O26: 4.5260527 | P26: 2.6600425 | Q26: 2.2919259 | R26: 1.7011314 | S26: 0.37749952 | T26: 4.4239216 | U26: 3.1563457 | V26: 2.5217255 | W26: 7.1852792 | X26: 1.9561074 | Y26: 1.8641879 | Z26: 2.358015 | AA26: 6.1438549 | AB26: 0.91829512
A27: Inflation, GDP deflator (annual %) | B27: NY.GDP.DEFL.KD.ZG | C27: Bermuda | D27: BMU | E27: 6.0335723 | F27: 6.4305905 | G27: 2.813884 | H27: 5.1963043 | I27: 1.9595642 | J27: 4.1784635 | K27: 29.3647 | L27: 4.0239039 | M27: 2.7415512 | N27: 2.7121495 | O27: -4.2363554 | P27: -1.3691962 | Q27: 8.580442 | R27: 2.82474 | S27: 4.6921434 | T27: 6.7623737 | U27: 5.3771711 | V27: 5.8664058 | W27: 2.0853376 | X27: 0.33366495 | Y27: 1.0489075 | Z27: -0.032572528 | AA27: 3.6551254 | AB27: ..
A28: Inflation, GDP deflator (annual %) | B28: NY.GDP.DEFL.KD.ZG | C28: Bhutan | D28: BTN | E28: 5.7088499 | F28: 8.7641477 | G28: 9.2967574 | H28: 8.1864621 | I28: 12.851991 | J28: 8.0478193 | K28: 8.0561273 | L28: 12.485398 | M28: 10.50963 | N28: 7.4353082 | O28: 2.2862093 | P28: 5.2663086 | Q28: 4.8812172 | R28: 3.0850745 | S28: 3.7909328 | T28: 5.857934 | U28: 5.411195 | V28: 3.1106604 | W28: 5.6530725 | X28: 4.8512511 | Y28: 5.9855106 | Z28: 9.1669159 | AA28: 10.650446 | AB28: 5.7161497
A29: Inflation, GDP deflator (annual %) | B29: NY.GDP.DEFL.KD.ZG | C29: Bolivia | D29: BOL | E29: 16.267938 | F29: 17.689443 | G29: 13.199204 | H29: 6.5571577 | I29: 7.9522082 | J29: 11.427281 | K29: 11.580209 | L29: 5.7050425 | M29: 7.0511278 | N29: 2.4115657 | O29: 5.1954044 | P29: 1.8700947 | Q29: 2.8207575 | R29: 6.329992 | S29: 7.9677087 | T29: 5.9407973 | U29: 13.66368 | V29: 7.3733536 | W29: 10.381182 | X29: -2.4198942 | Y29: 8.7775081 | Z29: 14.565892 | AA29: 6.914597 | AB29: 6.0077679
A30: Inflation, GDP deflator (annual %) | B30: NY.GDP.DEFL.KD.ZG | C30: Bosnia and Herzegovina | D30: BIH | E30: .. | F30: .. | G30: .. | H30: .. | I30: .. | J30: 8.8474311 | K30: -17.056763 | L30: 13.011481 | M30: -1.5819249 | N30: 8.3556508 | O30: 28.790136 | P30: 2.9619625 | Q30: 4.4615831 | R30: 0.91238477 | S30: 2.5724976 | T30: 3.8776273 | U30: 5.7284902 | V30: 5.7177923 | W30: 7.5565844 | X30: 0.051945393 | Y30: 2.2859525 | Z30: 2.3309419 | AA30: 0.60297475 | AB30: 1.9977767
A31: Inflation, GDP deflator (annual %) | B31: NY.GDP.DEFL.KD.ZG | C31: Botswana | D31: BWA | E31: 6.3000182 | F31: 5.1777104 | G31: 6.6392807 | H31: 13.0647 | I31: 9.4638049 | J31: 7.1552948 | K31: 16.112195 | L31: 5.2815377 | M31: 9.6633934 | N31: 14.235208 | O31: 14.170967 | P31: 8.3128251 | Q31: 1.1873707 | R31: 3.2590844 | S31: 10.078789 | T31: 15.471707 | U31: 7.875649 | V31: 4.5361282 | W31: 8.734782 | X31: 3.428869 | Y31: 18.921544 | Z31: 5.4546543 | AA31: 1.5946057 | AB31: 5.9064544
A32: Inflation, GDP deflator (annual %) | B32: NY.GDP.DEFL.KD.ZG | C32: Brazil | D32: BRA | E32: 2735.4885 | F32: 414.2356 | G32: 968.18423 | H32: 2001.3482 | I32: 2251.704 | J32: 93.522004 | K32: 17.085269 | L32: 7.6450029 | M32: 4.2359035 | N32: 8.4764493 | O32: 6.1778398 | P32: 8.9661797 | Q32: 10.555805 | R32: 13.726476 | S32: 8.0362173 | T32: 7.2129981 | U32: 6.1514402 | V32: 5.8645301 | W32: 8.3349497 | X32: 7.1851465 | Y32: 8.2285351 | Z32: 6.9688848 | AA32: 4.9293577 | AB32: 7.6255921
A33: Inflation, GDP deflator (annual %) | B33: NY.GDP.DEFL.KD.ZG | C33: Brunei Darussalam | D33: BRN | E33: 8.4099635 | F33: -2.8372807 | G33: 1.7268761 | H33: -2.9514906 | I33: -8.7636259 | J33: 2.8729978 | K33: 4.4887553 | L33: 8.5848536 | M33: -11.648574 | N33: 11.593978 | O33: 29.015709 | P33: -5.591899 | Q33: 0.37420917 | R33: 6.1046113 | S33: 15.886165 | T33: 18.76632 | U33: 10.047721 | V33: 1.120448 | W33: 12.69273 | X33: -22.091416 | Y33: 5.3087402 | Z33: 20.351114 | AA33: -0.048589631 | AB33: -3.1529121
A34: Inflation, GDP deflator (annual %) | B34: NY.GDP.DEFL.KD.ZG | C34: Bulgaria | D34: BGR | E34: 26.18799 | F34: 226.53787 | G34: 59.578649 | H34: 51.091054 | I34: 72.704969 | J34: 62.376649 | K34: 98.030635 | L34: 987.07049 | M34: 29.672229 | N34: 3.694683 | O34: 6.6300326 | P34: 6.1281009 | Q34: 4.6206137 | R34: 2.277877 | S34: 4.2199104 | T34: 7.3430637 | U34: 6.901073 | V34: 9.2335361 | W34: 8.4157098 | X34: 4.3335496 | Y34: 2.7937159 | Z34: 4.9142571 | AA34: 3.0738571 | AB34: -0.85765163
A35: Inflation, GDP deflator (annual %) | B35: NY.GDP.DEFL.KD.ZG | C35: Burkina Faso | D35: BFA | E35: 1.8100154 | F35: -3.9677808 | G35: 0.22705961 | H35: -1.4418398 | I35: 14.638962 | J35: 6.769569 | K35: 0.34870515 | L35: 1.5561999 | M35: 7.940316 | N35: 4.4364839 | O35: -1.6646694 | P35: 4.0661418 | Q35: 3.0569861 | R35: 1.4847288 | S35: 0.09064859 | T35: 3.7393854 | U35: -0.65963185 | V35: 2.2585138 | W35: 9.1619456 | X35: 2.3764028 | Y35: 7.1985968 | Z35: 3.2026759 | AA35: 1.9134616 | AB35: -1.9091507
A36: Inflation, GDP deflator (annual %) | B36: NY.GDP.DEFL.KD.ZG | C36: Burundi | D36: BDI | E36: 5.9855615 | F36: 4.0931408 | G36: 5.4017607 | H36: 7.7426457 | I36: 6.6384455 | J36: 16.102712 | K36: 14.453111 | L36: 32.397789 | M36: 11.450556 | N36: 14.95414 | O36: 38.944893 | P36: 13.716407 | Q36: 1.0278586 | R36: 11.945749 | S36: 13.146159 | T36: 18.856933 | U36: 2.845128 | V36: 6.9018753 | W36: 23.990943 | X36: 8.2473529 | Y36: 12.303296 | Z36: 14.294338 | AA36: 15.416499 | AB36: 13.452353
A37: Inflation, GDP deflator (annual %) | B37: NY.GDP.DEFL.KD.ZG | C37: Cambodia | D37: KHM | E37: 2.3453103 | F37: 4.7924188 | G37: -4.1158446 | H37: 49.354086 | I37: -29.172462 | J37: -1.5468995 | K37: -0.54613589 | L37: -0.83529133 | M37: -0.33599077 | N37: 7.6120783 | O37: -7.9011035 | P37: 5.1553351 | Q37: -0.36320894 | R37: 4.9210998 | S37: -6.332547 | T37: -1.7948832 | U37: 4.639771 | V37: 8.751419 | W37: 3.5459326 | X37: 2.1745981 | Y37: 0.50496457 | Z37: 2.6765122 | AA37: 0.64858299 | AB37: 3.4825689
A38: Inflation, GDP deflator (annual %) | B38: NY.GDP.DEFL.KD.ZG | C38: Cameroon | D38: CMR | E38: .. | F38: .. | G38: .. | H38: .. | I38: -4.41424 | J38: 11.515505 | K38: 3.5067149 | L38: 4.3860194 | M38: 10.01366 | N38: 1.981472 | O38: -3.2036247 | P38: 2.6428281 | Q38: 0.71614401 | R38: 1.7975225 | S38: 4.8237384 | T38: 6.0766799 | U38: 4.6299188 | V38: 6.5192442 | W38: 12.253787 | X38: 2.5043847 | Y38: 3.1205929 | Z38: 3.3640662 | AA38: 1.4405181 | AB38: 0.82821486
A39: Inflation, GDP deflator (annual %) | B39: NY.GDP.DEFL.KD.ZG | C39: Canada | D39: CAN | E39: 1.6430984 | F39: 3.5687135 | G39: -1.277671 | H39: 16.098656 | I39: 14.383143 | J39: 9.4843054 | K39: 2.6923792 | L39: 3.7377422 | M39: 3.6622322 | N39: 1.9485677 | O39: 2.8400676 | P39: 2.1785001 | Q39: 3.247868 | R39: 0.35809872 | S39: 1.5079707 | T39: 2.6312118 | U39: 3.9414724 | V39: 1.4311312 | W39: 4.7444412 | X39: -3.3385516 | Y39: 3 | Z39: 3.6991727 | AA39: 7.4355885 | AB39: 1.4354772
A40: Inflation, GDP deflator (annual %) | B40: NY.GDP.DEFL.KD.ZG | C40: Cape Verde | D40: CPV | E40: 3.3751796 | F40: 3.0711924 | G40: 1.4905335 | H40: 1.3228816 | I40: 1.4469047 | J40: 2.2384476 | K40: 1.756461 | L40: 1.1410801 | M40: -0.20737964 | N40: 1.8610517 | O40: 4.2723608 | P40: 1.6230619 | Q40: 1.2274263 | R40: 3.335092 | S40: 3.279353 | T40: 3.2088703 | U40: 2.7092892 | V40: 3.2384435 | W40: 3.8924299 | X40: -2.1442546 | Y40: 2.6468104 | Z40: 3.2388912 | AA40: 1.66904 | AB40: 1.2359855
A41: Inflation, GDP deflator (annual %) | B41: NY.GDP.DEFL.KD.ZG | C41: Cayman Islands | D41: CYM | E41: .. | F41: .. | G41: .. | H41: .. | I41: 3.0978032 | J41: .. | K41: .. | L41: .. | M41: .. | N41: .. | O41: .. | P41: .. | Q41: .. | R41: .. | S41: .. | T41: .. | U41: .. | V41: .. | W41: .. | X41: .. | Y41: .. | Z41: .. | AA41: .. | AB41: ..
A42: Inflation, GDP deflator (annual %) | B42: NY.GDP.DEFL.KD.ZG | C42: Central African Republic | D42: CAF | E42: 1.8367641 | F42: -0.38993188 | G42: 2.7826648 | H42: -3.4328953 | I42: 24.412511 | J42: 9.8980202 | K42: -3.5431378 | L42: 0.82331721 | M42: -0.41401283 | N42: 4.0846873 | O42: 8.5066207 | P42: 0.42589674 | Q42: -2.3718307 | R42: 1.3364015 | S42: -4.4398828 | T42: 5.1965653 | U42: 0.55077189 | V42: -2.3203694 | W42: 5.1480171 | X42: -3.3569916 | Y42: -1.4238785 | Z42: 1.9626477 | AA42: 2.7063442 | AB42: 7.163029
...

Sheet Standard Exchange Rates
A1: Year | C1: =C2&"y" -> 1960y | D1: =D2&"y" -> 1961y | E1: =E2&"y" -> 1962y | F1: =F2&"y" -> 1963y | G1: =G2&"y" -> 1964y | H1: =H2&"y" -> 1965y | I1: =I2&"y" -> 1966y | J1: =J2&"y" -> 1967y | ... XFD1: =XFD2&"y" -> y
A2: Country Name | B2: Country Code | C2: 1960 | D2: 1961 | E2: 1962 | F2: 1963 | G2: 1964 | H2: 1965 | I2: 1966 | J2: 1967 | K2: 1968 | L2: 1969 | M2: 1970 | N2: 1971 | O2: 1972 | P2: 1973 | Q2: 1974 | R2: 1975 | S2: 1976 | T2: 1977 | U2: 1978 | V2: 1979 | W2: 1980 | X2: 1981 | Y2: 1982 | Z2: 1983 | AA2: 1984 | AB2: 1985 | AC2: 1986 | AD2: 1987 | AE2: 1988 | AF2: 1989 | AG2: 1990 | AH2: 1991 | AI2: 1992 | AJ2: 1993 | AK2: 1994 | AL2: 1995 | AM2: 1996 | AN2: 1997 | AO2: 1998 | AP2: 1999 | AQ2: 2000 | AR2: 2001 | AS2: 2002 | AT2: 2003 | AU2: 2004 | AV2: 2005 | AW2: 2006 | AX2: 2007 | AY2: 2008 | AZ2: 2009 | BA2: 2010 | BB2: 2011 | BC2: 2012 | BD2: 2013
A3: Afghanistan | B3: AFG | C3: 193.90501 | D3: 193.90501 | E3: 193.90501 | F3: 395.88939 | G3: 436.28627 | H3: 436.28627 | I3: 436.28627 | J3: 436.28627 | K3: 436.28627 | L3: 436.28627 | M3: 436.28627 | N3: 436.28627 | O3: 436.28627 | P3: 436.28627 | Q3: 436.28627 | R3: 436.28627 | S3: 436.28627 | T3: 436.28627 | U3: 436.28627 | V3: 422.75332 | W3: 429.28953 | X3: 481.65196 | Y3: 490.57967 | Z3: 490.57967 | AA3: 490.57967 | AB3: 490.57967 | AC3: 490.57967 | AD3: 490.57967 | AE3: 490.57967 | AF3: 490.57967 | AG3: 490.57967 | AH3: 490.57967 | AI3: 490.57967 | AJ3: 490.57967 | AK3: 484.85948 | AL3: 36.567145 | AM3: 47.5 | AN3: 47.5 | AO3: 47.5 | AP3: 46.619531 | AQ3: 47.357575 | AR3: 47.500015 | AS3: 47.263 | AT3: 48.762754 | AU3: 47.845312 | AV3: 49.494597 | AW3: 49.925331 | AX3: 49.962018 | AY3: 50.249615 | AZ3: 50.325 | BA3: 46.452461 | BB3: 46.747008 | BC3: 50.9214 | BD3: 55.3775
A4: Albania | B4: ALB | C4: .. | D4: .. | E4: .. | F4: .. | G4: .. | H4: .. | I4: .. | J4: .. | K4: .. | L4: .. | M4: .. | N4: .. | O4: .. | P4: .. | Q4: .. | R4: .. | S4: .. | T4: .. | U4: .. | V4: .. | W4: .. | X4: .. | Y4: .. | Z4: .. | AA4: .. | AB4: .. | AC4: .. | AD4: .. | AE4: .. | AF4: .. | AG4: .. | AH4: .. | AI4: 75.0325 | AJ4: 102.0625 | AK4: 94.623333 | AL4: 92.6975 | AM4: 104.49892 | AN4: 148.93292 | AO4: 150.63333 | AP4: 137.69058 | AQ4: 143.70942 | AR4: 143.48483 | AS4: 140.15452 | AT4: 121.86325 | AU4: 102.78005 | AV4: 99.870254 | AW4: 98.103377 | AX4: 90.427894 | AY4: 83.894604 | AZ4: 94.97812 | BA4: 103.93644 | BB4: 100.89495 | BC4: 108.18464 | BD4: 105.66867
A5: Algeria | B5: DZA | C5: 4.93706 | D5: 4.93706 | E5: 4.93706 | F5: 4.93706 | G5: 4.93706 | H5: 4.93706 | I5: 4.93706 | J5: 4.93706 | K5: 4.93706 | L5: 4.93706 | M5: 4.93706 | N5: 4.9126383 | O5: 4.480515 | P5: 3.9624954 | Q5: 4.18075 | R5: 3.9494083 | S5: 4.163825 | T5: 4.1467583 | U5: 3.9659 | V5: 3.8532667 | W5: 3.83745 | X5: 4.3158083 | Y5: 4.5921917 | Z5: 4.7888 | AA5: 4.983375 | AB5: 5.0278 | AC5: 4.7023167 | AD5: 4.8497417 | AE5: 5.9147667 | AF5: 7.6085583 | AG5: 8.9575083 | AH5: 18.472875 | AI5: 21.836075 | AJ5: 23.345407 | AK5: 35.058501 | AL5: 47.662727 | AM5: 54.748933 | AN5: 57.70735 | AO5: 58.738958 | AP5: 66.573875 | AQ5: 75.259792 | AR5: 77.215021 | AS5: 79.6819 | AT5: 77.394975 | AU5: 72.06065 | AV5: 73.276308 | AW5: 72.646617 | AX5: 69.2924 | AY5: 64.5828 | AZ5: 72.647417 | BA5: 74.385983 | BB5: 72.937883 | BC5: 77.535967 | BD5: 79.3684
A6: American Samoa | B6: ASM | C6: .. | D6: .. | E6: .. | F6: .. | G6: .. | H6: .. | I6: .. | J6: .. | K6: .. | L6: .. | M6: .. | N6: .. | O6: .. | P6: .. | Q6: .. | R6: .. | S6: .. | T6: .. | U6: .. | V6: .. | W6: .. | X6: .. | Y6: .. | Z6: .. | AA6: .. | AB6: .. | AC6: .. | AD6: .. | AE6: .. | AF6: .. | AG6: .. | AH6: .. | AI6: .. | AJ6: .. | AK6: .. | AL6: .. | AM6: .. | AN6: .. | AO6: .. | AP6: .. | AQ6: .. | AR6: .. | AS6: .. | AT6: .. | AU6: .. | AV6: .. | AW6: .. | AX6: .. | AY6: .. | AZ6: .. | BA6: .. | BB6: .. | BC6: .. | BD6: ..
A7: Andorra | B7: AND | C7: .. | D7: .. | E7: .. | F7: .. | G7: .. | H7: .. | I7: .. | J7: .. | K7: .. | L7: .. | M7: .. | N7: .. | O7: .. | P7: .. | Q7: .. | R7: .. | S7: .. | T7: .. | U7: .. | V7: .. | W7: .. | X7: .. | Y7: .. | Z7: .. | AA7: .. | AB7: .. | AC7: .. | AD7: .. | AE7: .. | AF7: .. | AG7: .. | AH7: .. | AI7: .. | AJ7: .. | AK7: .. | AL7: .. | AM7: .. | AN7: .. | AO7: .. | AP7: .. | AQ7: .. | AR7: .. | AS7: .. | AT7: .. | AU7: .. | AV7: .. | AW7: .. | AX7: .. | AY7: .. | AZ7: .. | BA7: .. | BB7: .. | BC7: .. | BD7: ..
A8: Angola | B8: AGO | C8: 2.8668443e-08 | D8: 2.873486e-08 | E8: 2.8678443e-08 | F8: 2.8752027e-08 | G8: 2.8819777e-08 | H8: 2.8778527e-08 | I8: 2.882386e-08 | J8: 2.884161e-08 | K8: 2.872761e-08 | L8: 2.8561193e-08 | M8: 2.862511e-08 | N8: 2.819112e-08 | O8: 2.7052815e-08 | P8: 2.451462e-08 | Q8: 2.5407601e-08 | R8: 2.5552181e-08 | S8: 2.9383623e-08 | T8: 2.9918e-08 | U8: 2.9918e-08 | V8: 2.9918e-08 | W8: 2.9918e-08 | X8: 2.9918e-08 | Y8: 2.9918e-08 | Z8: 2.9918e-08 | AA8: 2.9918e-08 | AB8: 2.9918e-08 | AC8: 2.9918e-08 | AD8: 2.9918e-08 | AE8: 2.9918e-08 | AF8: 2.9918e-08 | AG8: 2.9918e-08 | AH8: 5.5098333e-08 | AI8: 2.5141667e-07 | AJ8: 2.6601667e-06 | AK8: 5.9515e-05 | AL8: 0.0027502296 | AM8: 0.12802917 | AN8: 0.22904008 | AO8: 0.39282352 | AP8: 2.7907062 | AQ8: 10.040544 | AR8: 22.057862 | AS8: 43.530207 | AT8: 74.606301 | AU8: 83.541363 | AV8: 87.159142 | AW8: 80.368072 | AX8: 76.706143 | AY8: 75.033354 | AZ8: 79.328167 | BA8: 91.90572 | BB8: 93.93475 | BC8: 95.467955 | BD8: 96.518279
A9: Antigua and Barbuda | B9: ATG | C9: 1.71429 | D9: 1.71429 | E9: 1.71429 | F9: 1.71429 | G9: 1.71429 | H9: 1.71429 | I9: 1.71429 | J9: 1.7619083 | K9: 2 | L9: 2 | M9: 2 | N9: 1.9748727 | O9: 1.9212781 | P9: 1.9592192 | Q9: 2.0532324 | R9: 2.1697958 | S9: 2.6146708 | T9: 2.7 | U9: 2.7 | V9: 2.7 | W9: 2.7 | X9: 2.7 | Y9: 2.7 | Z9: 2.7 | AA9: 2.7 | AB9: 2.7 | AC9: 2.7 | AD9: 2.7 | AE9: 2.7 | AF9: 2.7 | AG9: 2.7 | AH9: 2.7 | AI9: 2.7 | AJ9: 2.7 | AK9: 2.7 | AL9: 2.7 | AM9: 2.7 | AN9: 2.7 | AO9: 2.7 | AP9: 2.7 | AQ9: 2.7 | AR9: 2.7 | AS9: 2.7 | AT9: 2.7 | AU9: 2.7 | AV9: 2.7 | AW9: 2.7 | AX9: 2.7 | AY9: 2.7 | AZ9: 2.7 | BA9: 2.7 | BB9: 2.7 | BC9: 2.7 | BD9: 2.7
A10: Argentina | B10: ARG | C10: .. | D10: .. | E10: 8.7166667e-12 | F10: 1.3871667e-11 | G10: 1.4039167e-11 | H10: 1.6956667e-11 | I10: 2.0915e-11 | J10: 3.33425e-11 | K10: 3.5e-11 | L10: 3.5e-11 | M10: 3.7916667e-11 | N10: 4.5216667e-11 | O10: 5e-11 | P10: 5e-11 | Q10: 5e-11 | R10: 3.6575e-10 | S10: 1.3998333e-09 | T10: 4.0763333e-09 | U10: 7.9575e-09 | V10: 1.3169667e-08 | W10: 1.8371583e-08 | X10: 4.4026917e-08 | Y10: 2.5922533e-07 | Z10: 1.0529957e-06 | AA10: 6.7649117e-06 | AB10: 6.01809e-05 | AC10: 9.4303167e-05 | AD10: 0.00021442983 | AE10: 0.00087526042 | AF10: 0.042333961 | AG10: 0.48758908 | AH10: 0.95355442 | AI10: 0.99064167 | AJ10: 0.99894583 | AK10: 0.99900833 | AL10: 0.99975 | AM10: 0.9996625 | AN10: 0.9995 | AO10: 0.9995 | AP10: 0.9995 | AQ10: 0.9995 | AR10: 0.9995 | AS10: 3.0632567 | AT10: 2.9006292 | AU10: 2.9233008 | AV10: 2.9036575 | AW10: 3.0543133 | AX10: 3.0956488 | AY10: 3.1441646 | AZ10: 3.7101068 | BA10: 3.8962952 | BB10: 4.1101396 | BC10: 4.5369344 | BD10: 5.4593527
A11: Armenia | B11: ARM | C11: .. | D11: .. | E11: .. | F11: .. | G11: .. | H11: .. | I11: .. | J11: .. | K11: .. | L11: .. | M11: .. | N11: .. | O11: .. | P11: .. | Q11: .. | R11: .. | S11: .. | T11: .. | U11: .. | V11: .. | W11: .. | X11: .. | Y11: .. | Z11: .. | AA11: .. | AB11: .. | AC11: .. | AD11: .. | AE11: .. | AF11: .. | AG11: .. | AH11: .. | AI11: .. | AJ11: 9.105 | AK11: 288.65083 | AL11: 405.90833 | AM11: 414.0415 | AN11: 490.84679 | AO11: 504.915 | AP11: 535.06183 | AQ11: 539.52583 | AR11: 555.07826 | AS11: 573.35333 | AT11: 578.76295 | AU11: 533.45083 | AV11: 457.68694 | AW11: 416.04037 | AX11: 342.07912 | AY11: 305.9694 | AZ11: 363.28329 | BA11: 373.66047 | BB11: 372.50088 | BC11: 401.76398 | BD11: 409.62575
A12: Aruba | B12: ABW | C12: .. | D12: .. | E12: .. | F12: .. | G12: .. | H12: .. | I12: .. | J12: .. | K12: .. | L12: .. | M12: .. | N12: .. | O12: .. | P12: .. | Q12: .. | R12: .. | S12: .. | T12: .. | U12: .. | V12: .. | W12: .. | X12: .. | Y12: .. | Z12: .. | AA12: .. | AB12: .. | AC12: 1.79 | AD12: 1.79 | AE12: 1.79 | AF12: 1.79 | AG12: 1.79 | AH12: 1.79 | AI12: 1.79 | AJ12: 1.79 | AK12: 1.79 | AL12: 1.79 | AM12: 1.79 | AN12: 1.79 | AO12: 1.79 | AP12: 1.79 | AQ12: 1.79 | AR12: 1.79 | AS12: 1.79 | AT12: 1.79 | AU12: 1.79 | AV12: 1.79 | AW12: 1.79 | AX12: 1.79 | AY12: 1.79 | AZ12: 1.79 | BA12: 1.79 | BB12: 1.79 | BC12: 1.79 | BD12: 1.79
A13: Australia | B13: AUS | C13: 0.892857 | D13: 0.892857 | E13: 0.892857 | F13: 0.892857 | G13: 0.892857 | H13: 0.892857 | I13: 0.892857 | J13: 0.892857 | K13: 0.892857 | L13: 0.892857 | M13: 0.892857 | N13: 0.88267026 | O13: 0.83869781 | P13: 0.7034971 | Q13: 0.69666587 | R13: 0.76387125 | S13: 0.81828408 | T13: 0.901825 | U13: 0.87365925 | V13: 0.89464092 | W13: 0.87824433 | X13: 0.87021458 | Y13: 0.98586283 | Z13: 1.110015 | AA13: 1.1395192 | AB13: 1.431895 | AC13: 1.4959742 | AD13: 1.42818 | AE13: 1.2799083 | AF13: 1.2645967 | AG13: 1.2810567 | AH13: 1.2837558 | AI13: 1.3616483 | AJ13: 1.47056 | AK13: 1.3677508 | AL13: 1.3490325 | AM13: 1.2778633 | AN13: 1.34738 | AO13: 1.5918283 | AP13: 1.54995 | AQ13: 1.7248267 | AR13: 1.9334425 | AS13: 1.8405625 | AT13: 1.5419142 | AU13: 1.3597525 | AV13: 1.3094733 | AW13: 1.3279734 | AX13: 1.1950725 | AY13: 1.1921783 | AZ13: 1.2821888 | BA13: 1.0901595 | BB13: 0.9694632 | BC13: 0.96580103 | BD13: 1.0358431
A14: Austria | B14: AUT | C14: 26 | D14: 26 | E14: 26 | F14: 26 | G14: 26 | H14: 26 | I14: 26 | J14: 26 | K14: 26 | L14: 26 | M14: 26 | N14: 24.985584 | O14: 23.115333 | P14: 19.58 | Q14: 18.6925 | R14: 17.41675 | S14: 17.939667 | T14: 16.526917 | U14: 14.521667 | V14: 13.3675 | W14: 12.938 | X14: 15.926833 | Y14: 17.05925 | Z14: 17.963333 | AA14: 20.009083 | AB14: 20.6895 | AC14: 15.267133 | AD14: 12.6425 | AE14: 12.347667 | AF14: 13.230667 | AG14: 11.369833 | AH14: 11.675917 | AI14: 10.989333 | AJ14: 11.632183 | AK14: 11.421825 | AL14: 10.081496 | AM14: 10.586557 | AN14: 12.204244 | AO14: 12.379065 | AP14: .. | AQ14: .. | AR14: .. | AS14: .. | AT14: .. | AU14: .. | AV14: .. | AW14: .. | AX14: .. | AY14: .. | AZ14: .. | BA14: .. | BB14: .. | BC14: .. | BD14: ..
A15: Azerbaijan | B15: AZE | C15: .. | D15: .. | E15: .. | F15: .. | G15: .. | H15: .. | I15: .. | J15: .. | K15: .. | L15: .. | M15: .. | N15: .. | O15: .. | P15: .. | Q15: .. | R15: .. | S15: .. | T15: .. | U15: .. | V15: .. | W15: .. | X15: .. | Y15: .. | Z15: .. | AA15: .. | AB15: .. | AC15: .. | AD15: .. | AE15: .. | AF15: .. | AG15: .. | AH15: .. | AI15: 0.01084 | AJ15: 0.019995 | AK15: 0.314045 | AL15: 0.8827085 | AM15: 0.86025283 | AN15: 0.797075 | AO15: 0.77379969 | AP15: 0.82403333 | AQ15: 0.89483075 | AR15: 0.93131667 | AS15: 0.97216417 | AT15: 0.982146 | AU15: 0.9826955 | AV15: 0.945421 | AW15: 0.893445 | AX15: 0.85812381 | AY15: 0.82161958 | AZ15: 0.80378333 | BA15: 0.80265 | BB15: 0.78968639 | BC15: 0.78564535 | BD15: 0.78454108
A16: Bahamas, The | B16: BHS | C16: 1.02041 | D16: 1.02041 | E16: 1.02041 | F16: 1.02041 | G16: 1.02041 | H16: 1.02041 | I16: 1.02041 | J16: 1.02041 | K16: 1.02041 | L16: 1.02041 | M16: 1.0017008 | N16: 1 | O16: 1 | P16: 1 | Q16: 1 | R16: 1 | S16: 1 | T16: 1 | U16: 1 | V16: 1 | W16: 1 | X16: 1 | Y16: 1 | Z16: 1 | AA16: 1 | AB16: 1 | AC16: 1 | AD16: 1 | AE16: 1 | AF16: 1 | AG16: 1 | AH16: 1 | AI16: 1 | AJ16: 1 | AK16: 1 | AL16: 1 | AM16: 1 | AN16: 1 | AO16: 1 | AP16: 1 | AQ16: 1 | AR16: 1 | AS16: 1 | AT16: 1 | AU16: 1 | AV16: 1 | AW16: 1 | AX16: 1 | AY16: 1 | AZ16: 1 | BA16: 1 | BB16: 1 | BC16: 1 | BD16: 1
A17: Bahrain | B17: BHR | C17: .. | D17: .. | E17: .. | F17: .. | G17: .. | H17: .. | I17: 0.47619 | J17: 0.47619 | K17: 0.47619 | L17: 0.47619 | M17: 0.47619 | N17: 0.47479629 | O17: 0.43859778 | P17: 0.39963031 | Q17: 0.39474 | R17: 0.3955 | S17: 0.39559917 | T17: 0.39565 | U17: 0.38745333 | V17: 0.3816175 | W17: 0.37700023 | X17: 0.376 | Y17: 0.376 | Z17: 0.376 | AA17: 0.376 | AB17: 0.376 | AC17: 0.376 | AD17: 0.376 | AE17: 0.376 | AF17: 0.376 | AG17: 0.376 | AH17: 0.376 | AI17: 0.376 | AJ17: 0.37599999 | AK17: 0.37599996 | AL17: 0.37599997 | AM17: 0.37599997 | AN17: 0.37599996 | AO17: 0.37599996 | AP17: 0.37599998 | AQ17: 0.376 | AR17: 0.376 | AS17: 0.376 | AT17: 0.376 | AU17: 0.376 | AV17: 0.376 | AW17: 0.376 | AX17: 0.376 | AY17: 0.376 | AZ17: 0.376 | BA17: 0.376 | BB17: 0.376 | BC17: 0.376 | BD17: 0.376
A18: Bangladesh | B18: BGD | C18: .. | D18: .. | E18: .. | F18: .. | G18: .. | H18: .. | I18: .. | J18: .. | K18: .. | L18: .. | M18: .. | N18: 7.8688426 | O18: 7.7001842 | P18: 7.849816 | Q18: 8.2260022 | R18: 12.18618 | S18: 15.399169 | T18: 15.3751 | U18: 15.016117 | V18: 15.551925 | W18: 15.454058 | X18: 17.986692 | Y18: 22.117883 | Z18: 24.615425 | AA18: 25.353933 | AB18: 27.994592 | AC18: 30.4069 | AD18: 30.949833 | AE18: 31.733249 | AF18: 32.27 | AG18: 34.568808 | AH18: 36.596183 | AI18: 38.950758 | AJ18: 39.567257 | AK18: 40.211739 | AL18: 40.278318 | AM18: 41.794168 | AN18: 43.892116 | AO18: 46.905652 | AP18: 49.0854 | AQ18: 52.141667 | AR18: 55.806667 | AS18: 57.888 | AT18: 58.15004 | AU18: 59.512658 | AV18: 64.327475 | AW18: 68.933233 | AX18: 68.874875 | AY18: 68.598275 | AZ18: 69.039067 | BA18: 69.649292 | BB18: 74.1524 | BC18: 81.862658 | BD18: 78.103235
A19: Barbados | B19: BRB | C19: 1.71429 | D19: 1.71429 | E19: 1.71429 | F19: 1.71429 | G19: 1.71429 | H19: 1.71429 | I19: 1.71429 | J19: 1.7380992 | K19: 2 | L19: 2 | M19: 2 | N19: 1.9748762 | O19: 1.9212807 | P19: 1.9592205 | Q19: 2.0532309 | R19: 2.0188666 | S19: 2 | T19: 2 | U19: 2 | V19: 2 | W19: 2 | X19: 2 | Y19: 2 | Z19: 2 | AA19: 2 | AB19: 2 | AC19: 2 | AD19: 2 | AE19: 2 | AF19: 2 | AG19: 2 | AH19: 2 | AI19: 2 | AJ19: 2 | AK19: 2 | AL19: 2 | AM19: 2 | AN19: 2 | AO19: 2 | AP19: 2 | AQ19: 2 | AR19: 2 | AS19: 2 | AT19: 2 | AU19: 2 | AV19: 2 | AW19: 2 | AX19: 2 | AY19: 2 | AZ19: 2 | BA19: 2 | BB19: 2 | BC19: 2 | BD19: 2
A20: Belarus | B20: BLR | C20: .. | D20: .. | E20: .. | F20: .. | G20: .. | H20: .. | I20: .. | J20: .. | K20: .. | L20: .. | M20: .. | N20: .. | O20: .. | P20: .. | Q20: .. | R20: .. | S20: .. | T20: .. | U20: .. | V20: .. | W20: .. | X20: .. | Y20: .. | Z20: .. | AA20: .. | AB20: .. | AC20: .. | AD20: .. | AE20: .. | AF20: .. | AG20: .. | AH20: .. | AI20: .. | AJ20: .. | AK20: .. | AL20: 11.520967 | AM20: 13.229877 | AN20: 26.02055 | AO20: 46.12762 | AP20: 249.29533 | AQ20: 876.75 | AR20: 1390 | AS20: 1790.9167 | AT20: 2051.2708 | AU20: 2160.2575 | AV20: 2153.82 | AW20: 2144.5642 | AX20: 2146.0783 | AY20: 2136.3975 | AZ20: 2793.0492 | BA20: 2978.51 | BB20: 4974.6333 | BC20: 8336.8983 | BD20: 8880.0525
A21: Belgium | B21: BEL | C21: 50 | D21: 50 | E21: 50 | F21: 50 | G21: 50 | H21: 50 | I21: 50 | J21: 50 | K21: 50 | L21: 50 | M21: 50 | N21: 49.056977 | O21: 44.014583 | P21: 38.9765 | Q21: 38.9515 | R21: 36.778917 | S21: 38.605167 | T21: 35.84275 | U21: 31.492083 | V21: 29.318667 | W21: 29.241667 | X21: 37.12925 | Y21: 45.690583 | Z21: 51.131667 | AA21: 57.783917 | AB21: 59.378 | AC21: 44.671917 | AD21: 37.334083 | AE21: 36.768333 | AF21: 39.404 | AG21: 33.417917 | AH21: 34.14825 | AI21: 32.1495 | AJ21: 34.596521 | AK21: 33.456497 | AL21: 29.480017 | AM21: 30.961513 | AN21: 35.773891 | AO21: 36.298641 | AP21: .. | AQ21: .. | AR21: .. | AS21: .. | AT21: .. | AU21: .. | AV21: .. | AW21: .. | AX21: .. | AY21: .. | AZ21: .. | BA21: .. | BB21: .. | BC21: .. | BD21: ..
A22: Belize | B22: BLZ | C22: 1.42857 | D22: 1.42857 | E22: 1.42857 | F22: 1.42857 | G22: 1.42857 | H22: 1.42857 | I22: 1.42857 | J22: 1.4484117 | K22: 1.66667 | L22: 1.66667 | M22: 1.66667 | N22: 1.6436821 | O22: 1.6015618 | P22: 1.6326838 | Q22: 1.7109268 | R22: 1.8080437 | S22: 2.2256731 | T22: 2 | U22: 2 | V22: 2 | W22: 2 | X22: 2 | Y22: 2 | Z22: 2 | AA22: 2 | AB22: 2 | AC22: 2 | AD22: 2 | AE22: 2 | AF22: 2 | AG22: 2 | AH22: 2 | AI22: 2 | AJ22: 2 | AK22: 2 | AL22: 2 | AM22: 2 | AN22: 2 | AO22: 2 | AP22: 2 | AQ22: 2 | AR22: 2 | AS22: 2 | AT22: 2 | AU22: 2 | AV22: 2 | AW22: 2 | AX22: 2 | AY22: 2 | AZ22: 2 | BA22: 2 | BB22: 2 | BC22: 2 | BD22: 2
